Workbook

Sheet project
A1: attribute | B1: value
A2: project | B2: ssp-submission-workflow
A3: file_created | B3: 2024-12-17 08:10:51
A5: ssp-submission-workflow.url | B5: git@github.com:iiasa/ssp-submission-workflow
A6: ssp-submission-workflow.commit_hash | B6: 8c9ac62ec5b90382bf0d7ac679ae274b6aac992c
A7: ssp-submission-workflow.commit_timestamp | B7: 2024-12-17 08:09:58
A8: common-definitions.url | B8: https://github.com/IAMconsortium/common-definitions.git/
A9: common-definitions.commit_hash | B9: 99ec80c0e8473f6b172b07e18982bfdc4ae1a4d5
A10: common-definitions.commit_timestamp | B10: 2024-12-16 16:31:38

Sheet region
A1: region | B1: repository | C1: hierarchy | D1: description | E1: countries | F1: ar6 | G1: ssp | H1: navigate | I1: notes
A2: AIM 3.0|Brazil | B2: common-definitions | C2: AIM 3.0 | E2: ["Brazil"]
A3: AIM 3.0|Canada | B3: common-definitions | C3: AIM 3.0 | E3: ["Canada"]
A4: AIM 3.0|China | B4: common-definitions | C4: AIM 3.0 | E4: ["China", "Hong Kong"]
A5: AIM 3.0|EU & UK | B5: common-definitions | C5: AIM 3.0 | E5: ["Austria", "Belgium", "Cyprus", "Czechia", "Denmark", "Estonia", "Finland", "France", "Germany", "Greece", "Hungary", "Ireland", "Italy", "Latvia", "Lithuania", "Luxembourg", "Malta", "Netherlands", "Poland", "Portugal", "Slovakia", "Slovenia", "Spain", "Sweden", "United Kingdom"]
A6: AIM 3.0|Former USSR | B6: common-definitions | C6: AIM 3.0 | E6: ["Armenia", "Azerbaijan", "Belarus", "Georgia", "Kazakhstan", "Kyrgyzstan", "Moldova", "Russian Federation", "Tajikistan", "Turkmenistan", "Ukraine", "Uzbekistan"]
A7: AIM 3.0|India | B7: common-definitions | C7: AIM 3.0 | E7: ["India"]
A8: AIM 3.0|Japan | B8: common-definitions | C8: AIM 3.0 | E8: ["Japan"]
A9: AIM 3.0|Middle East | B9: common-definitions | C9: AIM 3.0 | E9: ["Bahrain", "Iran", "Iraq", "Israel", "Jordan", "Kuwait", "Lebanon", "Oman", "Qatar", "Saudi Arabia", "Syria", "United Arab Emirates", "Yemen"]
A10: AIM 3.0|New Zealand and Australia | B10: common-definitions | C10: AIM 3.0 | E10: ["Australia", "New Zealand"]
A11: AIM 3.0|North Africa | B11: common-definitions | C11: AIM 3.0 | E11: ["Algeria", "Egypt", "Libya", "Morocco", "Tunisia"]
A12: AIM 3.0|Other Africa | B12: common-definitions | C12: AIM 3.0 | E12: ["Angola", "Benin", "Botswana", "Burkina Faso", "Burundi", "Cabo Verde", "Cameroon", "Central African Republic", "Chad", "Comoros", "Congo", "C\u00f4te d'Ivoire", "Democratic Republic of the Congo", "Djibouti", "Equatorial Guinea", "Eritrea", "Eswatini", "Ethiopia", "Gabon", "Gambia", "Ghana", "Guinea", "Guinea-Bissau", "Kenya", "Lesotho", "Liberia", "Madagascar", "Malawi", "Mali", "Mauritania", "Mauritius", "Mayotte", "Mozambique", "Namibia", "Niger", "Nigeria", "Rwanda", "R\u00e9union", "Sao Tome and Principe", "Senegal", "Seychelles", "Sierra Leone", "Somalia", "South Africa", "Sudan", "Tanzania", "Togo", "Uganda", "Western Sahara", "Zambia", "Zimbabwe"]
A13: AIM 3.0|Rest of Asia | B13: common-definitions | C13: AIM 3.0 | E13: ["Afghanistan", "American Samoa", "Bangladesh", "Bhutan", "British Indian Ocean Territory", "Brunei Darussalam", "Christmas Island", "Cocos (Keeling) Islands", "Cook Islands", "Fiji", "French Polynesia", "French Southern Territories", "Guam", "Heard Island and McDonald Islands", "Kiribati", "Maldives", "Marshall Islands", "Micronesia", "Nauru", "Nepal", "New Caledonia", "Niue", "Norfolk Island", "Northern Mariana Islands", "Pakistan", "Palau", "Papua New Guinea", "Pitcairn", "Samoa", "Solomon Islands", "Sri Lanka", "Tokelau", "Tonga", "Tuvalu", "United States Minor Outlying Islands", "Vanuatu", "Wallis and Futuna"]
... A18: AIM 3.0|USA | B18: common-definitions | C18: AIM 3.0 | E18: ["United States"]
A19: AIM/Hub-Global 2.4|Brazil | B19: common-definitions | C19: AIM/Hub-Global 2.4
A20: AIM/Hub-Global 2.4|Canada | B20: common-definitions | C20: AIM/Hub-Global 2.4
A21: AIM/Hub-Global 2.4|China | B21: common-definitions | C21: AIM/Hub-Global 2.4
A22: AIM/Hub-Global 2.4|EU | B22: common-definitions | C22: AIM/Hub-Global 2.4
A23: AIM/Hub-Global 2.4|Former USSR | B23: common-definitions | C23: AIM/Hub-Global 2.4
A24: AIM/Hub-Global 2.4|India | B24: common-definitions | C24: AIM/Hub-Global 2.4
A25: AIM/Hub-Global 2.4|Japan | B25: common-definitions | C25: AIM/Hub-Global 2.4
A26: AIM/Hub-Global 2.4|Middle East | B26: common-definitions | C26: AIM/Hub-Global 2.4
A27: AIM/Hub-Global 2.4|New Zealand and Australia | B27: common-definitions | C27: AIM/Hub-Global 2.4
A28: AIM/Hub-Global 2.4|North Africa | B28: common-definitions | C28: AIM/Hub-Global 2.4
A29: AIM/Hub-Global 2.4|Other Africa | B29: common-definitions | C29: AIM/Hub-Global 2.4
A30: AIM/Hub-Global 2.4|Rest of Asia | B30: common-definitions | C30: AIM/Hub-Global 2.4
... A35: AIM/Hub-Global 2.4|USA | B35: common-definitions | C35: AIM/Hub-Global 2.4
A36: Africa (R10) | B36: common-definitions | C36: R10 | D36: Africa | E36: ["Algeria", "Angola", "Benin", "Botswana", "Burkina Faso", "Burundi", "Cameroon", "Cabo Verde", "Central African Republic", "Chad", "Comoros", "Congo", "C\u00f4te d'Ivoire", "Democratic Republic of the Congo", "Djibouti", "Egypt", "Equatorial Guinea", "Eritrea", "Ethiopia", "Gabon", "Gambia", "Ghana", "Guinea", "Guinea-Bissau", "Kenya", "Lesotho", "Liberia", "Libya", "Madagascar", "Malawi", "Mali", "Mauritania", "Mauritius", "Mayotte", "Morocco", "Mozambique", "Namibia", "Niger", "Nigeria", "Rwanda", "R\u00e9union", "Sao Tome and Principe", "Senegal", "Seychelles", "Sierra Leone", "Somalia", "South Africa", "South Sudan", "Sudan", "Eswatini", "Togo", "Tunisia", "Uganda", "Tanzania", "Western Sahara", "Zambia", "Zimbabwe"] | F36: R10AFRICA | I36: Depending on the spatial resolution, some models report Northern Africa as part of the Middle East region.
A37: African Union | B37: common-definitions | C37: G20 members
A38: Argentina | B38: common-definitions | C38: G20 members
A39: Asia (R5) | B39: common-definitions | C39: R5 | D39: The region includes Asian countries with the exception of the Middle East, Japan and Former Soviet Union states | E39: ["Afghanistan", "Bangladesh", "Bhutan", "Brunei Darussalam", "Cambodia", "China", "Cook Islands", "Fiji", "French Polynesia", "Hong Kong", "India", "Indonesia", "Kiribati", "Laos", "Macao", "Malaysia", "Maldives", "Marshall Islands", "Micronesia", "Mongolia", "Myanmar", "Nauru", "Nepal", "Niue", "New Caledonia", "North Korea", "Pakistan", "Papua New Guinea", "Palau", "Philippines", "South Korea", "Samoa", "Singapore", "Solomon Islands", "Sri Lanka", "Taiwan", "Thailand", "Timor-Leste", "Tonga", "Tuvalu", "Vanuatu", "Viet Nam"] | F39: R5ASIA | G39: R5.2ASIA
A40: Australia | B40: common-definitions | C40: G20 members
A41: Brazil | B41: common-definitions | C41: G20 members
A42: COFFEE 1.5|Africa (excluding South Africa) | B42: common-definitions | C42: COFFEE 1.5 | E42: ["Algeria", "Angola", "Benin", "Botswana", "Burkina Faso", "Burundi", "Cabo Verde", "Cameroon", "Central African Republic", "Chad", "Comoros", "Congo", "C\u00f4te d'Ivoire", "Democratic Republic of the Congo", "Djibouti", "Egypt", "Equatorial Guinea", "Eritrea", "Eswatini", "Ethiopia", "Gabon", "Gambia", "Ghana", "Guinea", "Guinea-Bissau", "Kenya", "Lesotho", "Liberia", "Libya", "Madagascar", "Malawi", "Mali", "Mauritania", "Mauritius", "Mayotte", "Morocco", "Mozambique", "Namibia", "Niger", "Nigeria", "Rwanda", "R\u00e9union", "Sao Tome and Principe", "Senegal", "Seychelles", "Sierra Leone", "Somalia", "South Sudan", "Sudan", "Tanzania", "Togo", "Tunisia", "Uganda", "Western Sahara", "Zambia"]
A43: COFFEE 1.5|Australia & New Zealand | B43: common-definitions | C43: COFFEE 1.5 | E43: ["Australia", "New Zealand"]
A44: COFFEE 1.5|Brazil | B44: common-definitions | C44: COFFEE 1.5 | E44: ["Brazil"]
A45: COFFEE 1.5|Canada | B45: common-definitions | C45: COFFEE 1.5 | E45: ["Canada", "Saint Helena, Ascension and Tristan da Cunha", "Saint Pierre and Miquelon"]
A46: COFFEE 1.5|Caspian Sea | B46: common-definitions | C46: COFFEE 1.5 | E46: ["Afghanistan", "Armenia", "Azerbaijan", "Georgia", "Kazakhstan", "Kyrgyzstan", "Pakistan", "Tajikistan", "Turkmenistan", "Uzbekistan"]
A47: COFFEE 1.5|Central America | B47: common-definitions | C47: COFFEE 1.5 | E47: ["Anguilla", "Antigua and Barbuda", "Aruba", "Bahamas", "Barbados", "Belize", "Bermuda", "Bonaire, Sint Eustatius and Saba", "Cayman Islands", "Costa Rica", "Cuba", "Cura\u00e7ao", "Dominica", "Dominican Republic", "El Salvador", "French Guiana", "Grenada", "Guadeloupe", "Guatemala", "Guyana", "Haiti", "Honduras", "Jamaica", "Martinique", "Mexico", "Montserrat", "Nicaragua", "Panama", "Saint Barth\u00e9lemy", "Saint Kitts and Nevis", "Saint Lucia", "Saint Martin (French part)", "Saint Vincent and the Grenadines", "Sint Maarten (Dutch part)", "Suriname", "Trinidad and Tobago", "Turks and Caicos Islands"]
A48: COFFEE 1.5|China | B48: common-definitions | C48: COFFEE 1.5 | E48: ["China", "Hong Kong", "Macao"]
...

Sheet variable
A1: variable | B1: description | C1: repository | D1: unit | E1: tier | F1: weight | G1: notes | H1: navigate | I1: range | J1: sdg | K1: min | L1: lower_bound | M1: drop_negative_weights | N1: engage | O1: shape | P1: skip-region-aggregation | Q1: agmip | R1: components
A2: Agricultural Demand | B2: Total demand for food, non-food and feed products (crops and livestock) and bioenergy crops (1st & 2nd generation) | C2: common-definitions | D2: million t DM/yr | E2: 1 | Q2: Domestic use (CONS)
A3: Agricultural Demand|Crops | B3: Demand for crops including food, feed products and bioenergy (1st & 2nd generation crops) | C3: common-definitions | D3: million t DM/yr | E3: 1 | Q3: Domestic use (CONS) - Crops (CRP)
A4: Agricultural Demand|Crops|Bioenergy | B4: Demand for bioenergy crops (1st & 2nd generation) | C4: common-definitions | D4: million t DM/yr | E4: 1
A5: Agricultural Demand|Crops|Bioenergy|1st Generation | B5: Demand for 1st generation bioenergy crops (sugar, starch and oil crops) | C5: common-definitions | D5: million t DM/yr | E5: 2
A6: Agricultural Demand|Crops|Bioenergy|2nd generation | B6: Demand for second-generation bioenergy crops (short rotation grasses, short rotation trees) | C6: common-definitions | D6: million t DM/yr | E6: 1 | Q6: Domestic use (CONS) - Energy Crops (ECP)
A7: Agricultural Demand|Crops|Feed | B7: Demand for feed crops | C7: common-definitions | D7: million t DM/yr | E7: 2 | Q7: Feed demand (FEED) - Crops (CRP)
A8: Agricultural Demand|Crops|Feed|Cereals | B8: Demand for feed crops - cereals (maize, rice, temperate cereals and tropical cereals) | C8: common-definitions | D8: million t DM/yr | E8: 3
A9: Agricultural Demand|Crops|Feed|Oil Crops | B9: Demand for feed crops - oil crops (cotton seed, groundnuts, oilpalms, other oil crops incl rapeseed, soybean, sunflower) | C9: common-definitions | D9: million t DM/yr | E9: 3
A10: Agricultural Demand|Crops|Feed|Other Crops | B10: Demand for feed crops - other crops (fruits, vegetables, nuts, potatoes, pulses, tropical roots) | C10: common-definitions | D10: million t DM/yr | E10: 3
A11: Agricultural Demand|Crops|Feed|Sugar Crops | B11: Demand for feed crops - sugar crops (sugar beet, sugar cane) | C11: common-definitions | D11: million t DM/yr | E11: 3
A12: Agricultural Demand|Crops|Food | B12: Demand for food crops | C12: common-definitions | D12: million t DM/yr | E12: 2 | Q12: Food demand (FOOD) - Crops (CRP)
A13: Agricultural Demand|Crops|Food|Cereals | B13: Demand for food crops - cereals (maize, rice, temperate cereals and tropical cereals) | C13: common-definitions | D13: million t DM/yr | E13: 3
A14: Agricultural Demand|Crops|Food|Oil Crops | B14: Demand for food crops - oil crops (cotton seed, groundnuts, oilpalms, other oil crops incl rapeseed, soybean, sunflower) | C14: common-definitions | D14: million t DM/yr | E14: 3
A15: Agricultural Demand|Crops|Food|Other Crops | B15: Demand for food crops - other crops (fruits, vegetables, nuts, potatoes, pulses, tropical roots) | C15: common-definitions | D15: million t DM/yr | E15: 3
A16: Agricultural Demand|Crops|Food|Sugar Crops | B16: Demand for food crops - sugar crops (sugar beet, sugar cane) | C16: common-definitions | D16: million t DM/yr | E16: 3
A17: Agricultural Demand|Crops|Other | B17: Demand for crops for other uses | C17: common-definitions | D17: million t DM/yr | E17: 2
A18: Agricultural Demand|Livestock | B18: Demand for livestock products (excluding fish) | C18: common-definitions | D18: million t DM/yr | E18: 1 | Q18: Domestic use (CONS) - LSP
A19: Agricultural Demand|Livestock|Feed | B19: Demand for livestock products used as feed (excluding fish) | C19: common-definitions | D19: million t DM/yr | E19: 2
A20: Agricultural Demand|Livestock|Food | B20: Demand for livestock products used as food (excluding fish) | C20: common-definitions | D20: million t DM/yr | E20: 2 | Q20: Food demand (FOOD) - Livestock (LSP)
A21: Agricultural Demand|Livestock|Food|Dairy | B21: Demand for livestock products used as food - dairy products (milk, eggs) | C21: common-definitions | D21: million t DM/yr | E21: 3
A22: Agricultural Demand|Livestock|Food|Non-Ruminant | B22: Demand for livestock products used as food - monogastric meat (pig, poultry) | C22: common-definitions | D22: million t DM/yr | E22: 3
A23: Agricultural Demand|Livestock|Food|Ruminant | B23: Demand for livestock products used as food - ruminant meat (cattle, goat, sheep) | C23: common-definitions | D23: million t DM/yr | E23: 3
A24: Agricultural Demand|Livestock|Other | B24: Demand for livestock products for other uses | C24: common-definitions | D24: million t DM/yr | E24: 2
A25: Agricultural Demand|Residues | B25: Demand for residues from agricultural production for feed, bioenergy and other uses | C25: common-definitions | D25: million t DM/yr | E25: 2
A26: Agricultural Demand|Residues|Bioenergy | B26: Demand for residues as bioenergy | C26: common-definitions | D26: million t DM/yr | E26: 2
A27: Agricultural Demand|Residues|Feed | B27: Demand for residues as feed | C27: common-definitions | D27: million t DM/yr | E27: 2
A28: Agricultural Demand|Residues|Other | B28: Demand of residues for other uses | C28: common-definitions | D28: million t DM/yr | E28: 2
A29: Agricultural Material Footprint [per capita] | B29: Biomass usage per capita excluding pasture and forestry | C29: common-definitions | D29: tDM/cap/yr | F29: Population | J29: 12 | O29: Agricultural Material Footprint
A30: Agricultural Production | B30: Total production of food, non-food and feed products (crops and livestock) and bioenergy crops (1st & 2nd generation) | C30: common-definitions | D30: million t DM/yr | E30: 1 | Q30: Production (PROD)
A31: Agricultural Production|Crops | B31: Production of crops | C31: common-definitions | D31: million t DM/yr | E31: 1 | Q31: Production (PROD) - All crops (CRP)
A32: Agricultural Production|Crops|Cereals | B32: Production of cereals (maize, rice, temperate cereals and tropical cereals) | C32: common-definitions | D32: million t DM/yr | E32: 2
A33: Agricultural Production|Crops|Energy Crops | B33: Production of second-generation bioenergy crops (short rotation grasses, short rotation trees) | C33: common-definitions | D33: million t DM/yr | E33: 2
A34: Agricultural Production|Crops|Oil Crops | B34: Production of oil crops (cotton seed, groundnuts, oilpalms, other oil crops incl rapeseed, soybean, sunflower) | C34: common-definitions | D34: million t DM/yr | E34: 2
A35: Agricultural Production|Crops|Other Crops | B35: Production of other crops (fruits, vegetables, nuts, potatoes, pulses, tropical roots) | C35: common-definitions | D35: million t DM/yr | E35: 2
A36: Agricultural Production|Crops|Sugar Crops | B36: Production of sugar crops (sugar beet, sugar cane) | C36: common-definitions | D36: million t DM/yr | E36: 2
A37: Agricultural Production|Livestock | B37: Production of livestock products (excluding fish) | C37: common-definitions | D37: million t DM/yr | E37: 1 | Q37: Production (PROD) - Livestock (LSP)
A38: Agricultural Production|Livestock|Dairy | B38: Production of dairy products (milk, eggs) | C38: common-definitions | D38: million t DM/yr | E38: 2 | Q38: Production (PROD) - Dairy (DRY)
A39: Agricultural Production|Livestock|Non-Ruminant | B39: Production of monogastric meat (pig, poultry) | C39: common-definitions | D39: million t DM/yr | E39: 2 | Q39: Production (PROD) - Dairy (DRY)
A40: Agricultural Production|Livestock|Ruminant | B40: Production of ruminant meat (cattle, goat, sheep) | C40: common-definitions | D40: million t DM/yr | E40: 2 | Q40: Production (PROD) - Dairy (DRY)
...

Sheet scenario
A1: scenario | B1: description
A2: SSP1 - High Emissions | B2: 'Sustainability – Taking the Green Road' (SSP1) combined with 'High Emissions' climate policy assumptions following the ScenarioMIP protocol
A3: SSP1 - High Emissions_a | B3: 'Sustainability – Taking the Green Road' (SSP1) combined with 'High Emissions' Option a climate policy assumptions following the ScenarioMIP protocol
A4: SSP1 - High Emissions_b | B4: 'Sustainability – Taking the Green Road' (SSP1) combined with 'High Emissions' Option b climate policy assumptions following the ScenarioMIP protocol
A5: SSP1 - High Emissions_c | B5: 'Sustainability – Taking the Green Road' (SSP1) combined with 'High Emissions' Option c climate policy assumptions following the ScenarioMIP protocol
A6: SSP1 - High Emissions_d | B6: 'Sustainability – Taking the Green Road' (SSP1) combined with 'High Emissions' Option d climate policy assumptions following the ScenarioMIP protocol
A7: SSP1 - High Emissions_e | B7: 'Sustainability – Taking the Green Road' (SSP1) combined with 'High Emissions' Option e climate policy assumptions following the ScenarioMIP protocol
A8: SSP1 - High Emissions_f | B8: 'Sustainability – Taking the Green Road' (SSP1) combined with 'High Emissions' Option f climate policy assumptions following the ScenarioMIP protocol
A9: SSP1 - High Emissions_g | B9: 'Sustainability – Taking the Green Road' (SSP1) combined with 'High Emissions' Option g climate policy assumptions following the ScenarioMIP protocol
A10: SSP1 - High Emissions_h | B10: 'Sustainability – Taking the Green Road' (SSP1) combined with 'High Emissions' Option h climate policy assumptions following the ScenarioMIP protocol
A11: SSP1 - High Emissions_i | B11: 'Sustainability – Taking the Green Road' (SSP1) combined with 'High Emissions' Option i climate policy assumptions following the ScenarioMIP protocol
A12: SSP1 - High Emissions_j | B12: 'Sustainability – Taking the Green Road' (SSP1) combined with 'High Emissions' Option j climate policy assumptions following the ScenarioMIP protocol
... A911: SSP5 - Very Low Emissions_z | B911: 'Fossil-fueled Development – Taking the Highway' (SSP5) combined with 'Very Low Emissions' Option z climate policy assumptions following the ScenarioMIP protocol

Sheet data
A1: Model | B1: Scenario | C1: Region | D1: Variable | E1: Unit | F1: 2005 | G1: 2010 | H1: 2015 | I1: 2020 | J1: 2025 | K1: 2030 | L1: 2035 | M1: 2040 | N1: 2045 | O1: 2050 | P1: 2060 | Q1: 2070 | R1: 2080 | S1: 2090 | T1: 2100
A2: IMAGE | B2: SSP1_NO_GAP_ELEC | C2: BRA | D2: Emissions|CO2|Energy | E2: Mt CO2/yr | F2: 320.61008 | G2: 375.03436 | H2: 470.75158 | I2: 394.82118 | J2: 471.55022 | K2: 456.54876 | L2: 470.99871 | M2: 673.70969 | N2: 1045.4327 | O2: 1228.832 | P2: 1231.4086 | Q2: 1026.9047 | R2: 693.13494 | S2: 483.89952 | T2: 482.33421
A3: IMAGE | B3: SSP1_NO_GAP_ELEC | C3: CAN | D3: Emissions|CO2|Energy | E3: Mt CO2/yr | F3: 557.70878 | G3: 542.63181 | H3: 575.04185 | I3: 545.5593 | J3: 582.56698 | K3: 597.24903 | L3: 530.92309 | M3: 483.22851 | N3: 430.5576 | O3: 401.92057 | P3: 401.37056 | Q3: 431.36023 | R3: 464.46547 | S3: 441.84543 | T3: 424.32537
A4: IMAGE | B4: SSP1_NO_GAP_ELEC | C4: CEU | D4: Emissions|CO2|Energy | E4: Mt CO2/yr | F4: 751.82691 | G4: 756.48684 | H4: 714.08261 | I4: 692.84929 | J4: 753.61919 | K4: 778.05678 | L4: 692.15299 | M4: 594.94343 | N4: 473.9999 | O4: 398.71736 | P4: 361.10055 | Q4: 371.97343 | R4: 343.3924 | S4: 242.03773 | T4: 217.16086
A5: IMAGE | B5: SSP1_NO_GAP_ELEC | C5: CHN | D5: Emissions|CO2|Energy | E5: Mt CO2/yr | F5: 5929.6088 | G5: 8461.0716 | H5: 9738.1934 | I5: 10515.703 | J5: 10923.235 | K5: 10072.191 | L5: 9488.1857 | M5: 8686.8647 | N5: 7412.4084 | O5: 6165.7748 | P5: 4657.213 | Q5: 4081.2051 | R5: 3330.1454 | S5: 2995.5632 | T5: 2716.1155
A6: IMAGE | B6: SSP1_NO_GAP_ELEC | C6: EAF | D6: Emissions|CO2|Energy | E6: Mt CO2/yr | F6: 42.062753 | G6: 59.453861 | H6: 74.949273 | I6: 80.560847 | J6: 102.98944 | K6: 155.98715 | L6: 224.8011 | M6: 351.70384 | N6: 453.74266 | O6: 515.18719 | P6: 568.43382 | Q6: 480.43746 | R6: 641.43751 | S6: 748.76595 | T6: 879.63812
A7: IMAGE | B7: SSP1_NO_GAP_ELEC | C7: INDIA | D7: Emissions|CO2|Energy | E7: Mt CO2/yr | F7: 1065.1957 | G7: 1563.1102 | H7: 2030.115 | I7: 2068.4782 | J7: 2841.5722 | K7: 3253.3641 | L7: 3601.6036 | M7: 3917.375 | N7: 4083.1782 | O7: 4265.5764 | P7: 4994.9865 | Q7: 5635.3548 | R7: 6087.2496 | S7: 6504.8867 | T7: 6427.3512
A8: IMAGE | B8: SSP1_NO_GAP_ELEC | C8: INDO | D8: Emissions|CO2|Energy | E8: Mt CO2/yr | F8: 327.43232 | G8: 419.24776 | H8: 477.68635 | I8: 560.23222 | J8: 718.40122 | K8: 835.34806 | L8: 988.68295 | M8: 1144.9317 | N8: 1273.7512 | O8: 1371.9343 | P8: 1617.3139 | Q8: 1767.1137 | R8: 1792.5695 | S8: 1889.9012 | T8: 1882.0517
A9: IMAGE | B9: SSP1_NO_GAP_ELEC | C9: JAP | D9: Emissions|CO2|Energy | E9: Mt CO2/yr | F9: 1187.7723 | G9: 1125.0121 | H9: 1138.8146 | I9: 943.76658 | J9: 960.87383 | K9: 883.05471 | L9: 790.12595 | M9: 716.15534 | N9: 682.44329 | O9: 677.90324 | P9: 634.11481 | Q9: 623.39311 | R9: 604.47239 | S9: 500.37532 | T9: 377.30478
A10: IMAGE | B10: SSP1_NO_GAP_ELEC | C10: KOR | D10: Emissions|CO2|Energy | E10: Mt CO2/yr | F10: 528.66295 | G10: 614.13991 | H10: 633.48741 | I10: 601.59659 | J10: 600.28611 | K10: 602.83632 | L10: 566.75448 | M10: 514.46668 | N10: 466.01975 | O10: 456.51136 | P10: 428.00341 | Q10: 351.42472 | R10: 282.21387 | S10: 267.45322 | T10: 283.95907
A11: IMAGE | B11: SSP1_NO_GAP_ELEC | C11: ME | D11: Emissions|CO2|Energy | E11: Mt CO2/yr | F11: 1275.4618 | G11: 1614.2552 | H11: 1879.7915 | I11: 1968.5021 | J11: 2157.4241 | K11: 2263.7121 | L11: 2438.0766 | M11: 2452.6627 | N11: 2517.3162 | O11: 2551.2864 | P11: 2631.3125 | Q11: 2668.6752 | R11: 2456.6512 | S11: 2228.0921 | T11: 2031.2982
A12: IMAGE | B12: SSP1_NO_GAP_ELEC | C12: MEX | D12: Emissions|CO2|Energy | E12: Mt CO2/yr | F12: 447.34397 | G12: 466.65595 | H12: 479.08371 | I12: 378.59507 | J12: 470.63941 | K12: 472.21789 | L12: 481.95732 | M12: 542.56805 | N12: 421.39095 | O12: 407.58629 | P12: 457.41007 | Q12: 455.31089 | R12: 458.95631 | S12: 541.46142 | T12: 434.29869
A13: IMAGE | B13: SSP1_NO_GAP_ELEC | C13: NAF | D13: Emissions|CO2|Energy | E13: Mt CO2/yr | F13: 360.78778 | G13: 427.94437 | H13: 493.90918 | I13: 484.94342 | J13: 603.23266 | K13: 677.83248 | L13: 738.69471 | M13: 803.54926 | N13: 893.36865 | O13: 977.57436 | P13: 1084.5725 | Q13: 1202.8574 | R13: 1271.589 | S13: 1303.1945 | T13: 1202.512
... A2350: IMAGE | B2350: SSP1_NO_GAP_ELEC | C2350: World | D2350: Private consumption|Household | E2350: US$2005ppp/capita | F2350: 0 | G2350: 0 | H2350: 0 | I2350: 0 | J2350: 0 | K2350: 0 | L2350: 0 | M2350: 0 | N2350: 0 | O2350: 0 | P2350: 0 | Q2350: 0 | R2350: 0 | S2350: 0 | T2350: 0

Sheet Priority-Emissions
A1: Model | B1: Scenario | C1: Region | D1: Variable | E1: Unit | F1: 2005 | G1: 2010 | H1: 2015 | I1: 2020 | J1: 2021 | K1: 2022 | L1: 2023 | M1: 2024 | N1: 2025 | O1: 2030 | P1: 2035 | Q1: 2040 | R1: 2045 | S1: 2050 | T1: 2060 | U1: 2070 | V1: 2080 | W1: 2090 | X1: 2100
D2: Emissions|BC|Energy|Supply | E2: Mt BC/yr
D3: Emissions|CH4|Energy|Supply | E3: Mt CH4/yr
D4: Emissions|CO2|Energy|Supply | E4: Mt CO2/yr
D5: Emissions|CO|Energy|Supply | E5: Mt CO/yr
D6: Emissions|N2O|Energy|Supply | E6: kt N2O/yr
D7: Emissions|NH3|Energy|Supply | E7: Mt NH3/yr
D8: Emissions|NOx|Energy|Supply | E8: Mt NO2/yr
D9: Emissions|OC|Energy|Supply | E9: Mt OC/yr
D10: Emissions|Sulfur|Energy|Supply | E10: Mt SO2/yr
D11: Emissions|VOC|Energy|Supply | E11: Mt VOC/yr
D12: Emissions|BC|Energy|Demand|Industry | E12: Mt BC/yr
D13: Emissions|CH4|Energy|Demand|Industry | E13: Mt CH4/yr
... D163: Emissions|F-Gases | E163: Mt CO2-equiv/yr

Sheet Priority-Energy
A1: Model | B1: Scenario | C1: Region | D1: Variable | E1: Unit | F1: 2005 | G1: 2010 | H1: 2015 | I1: 2020 | J1: 2021 | K1: 2022 | L1: 2023 | M1: 2024 | N1: 2025 | O1: 2030 | P1: 2035 | Q1: 2040 | R1: 2045 | S1: 2050 | T1: 2060 | U1: 2070 | V1: 2080 | W1: 2090 | X1: 2100
D2: Capacity|Electricity|Biomass | E2: =VLOOKUP(D2,variable!$A$2:$D$12140,4,FALSE) -> GW
D3: Capacity|Electricity|Biomass|w/o CCS | E3: =VLOOKUP(D3,variable!$A$2:$D$12140,4,FALSE) -> GW
D4: Capacity|Electricity|Coal | E4: =VLOOKUP(D4,variable!$A$2:$D$12140,4,FALSE) -> GW
D5: Capacity|Electricity|Coal|w/o CCS | E5: =VLOOKUP(D5,variable!$A$2:$D$12140,4,FALSE) -> GW
D6: Capacity|Electricity|Gas | E6: =VLOOKUP(D6,variable!$A$2:$D$12140,4,FALSE) -> GW
D7: Capacity|Electricity|Gas|w/o CCS | E7: =VLOOKUP(D7,variable!$A$2:$D$12140,4,FALSE) -> GW
D8: Capacity|Electricity|Geothermal | E8: =VLOOKUP(D8,variable!$A$2:$D$12140,4,FALSE) -> GW
D9: Capacity|Electricity|Hydro | E9: =VLOOKUP(D9,variable!$A$2:$D$12140,4,FALSE) -> GW
D10: Capacity|Electricity|Nuclear | E10: =VLOOKUP(D10,variable!$A$2:$D$12140,4,FALSE) -> GW
D11: Capacity|Electricity|Oil | E11: =VLOOKUP(D11,variable!$A$2:$D$12140,4,FALSE) -> GW
D12: Capacity|Electricity|Oil|w/o CCS | E12: =VLOOKUP(D12,variable!$A$2:$D$12140,4,FALSE) -> GW
D13: Capacity|Electricity|Solar | E13: =VLOOKUP(D13,variable!$A$2:$D$12140,4,FALSE) -> GW
... D85: Carbon Capture|Geological Storage|Fossil | E85: =VLOOKUP(D85,variable!$A$2:$D$12140,4,FALSE) -> Mt CO2/yr

Sheet All Tier 1 & Priority
A1: Model | B1: Scenario | C1: Region | D1: Variable | E1: Unit | F1: 2005 | G1: 2010 | H1: 2015 | I1: 2020 | J1: 2025 | K1: 2030 | L1: 2035 | M1: 2040 | N1: 2045 | O1: 2050 | P1: 2060 | Q1: 2070 | R1: 2080 | S1: 2090 | T1: 2100
D2: Agricultural Demand | E2: million t DM/yr
D3: Agricultural Demand|Crops | E3: million t DM/yr
D4: Agricultural Demand|Crops|Bioenergy | E4: million t DM/yr
D5: Agricultural Demand|Crops|Bioenergy|2nd generation | E5: million t DM/yr
D6: Agricultural Demand|Livestock | E6: million t DM/yr
D7: Agricultural Production | E7: million t DM/yr
D8: Agricultural Production|Crops | E8: million t DM/yr
D9: Agricultural Production|Livestock | E9: million t DM/yr
D10: Capacity|Electricity | E10: GW
D11: Capacity|Electricity|Ammonia | E11: GW
D12: Capacity|Electricity|Biomass | E12: GW
D13: Capacity|Electricity|Biomass|w/ CCS | E13: GW
D14: Capacity|Electricity|Biomass|w/o CCS | E14: GW
D15: Capacity|Electricity|Coal | E15: =VLOOKUP(D15,variable!$A$2:$D$12140,4,FALSE) -> GW
D16: Capacity|Electricity|Coal|w/ CCS | E16: GW
D17: Capacity|Electricity|Coal|w/o CCS | E17: GW
D18: Capacity|Electricity|Fossil | E18: GW
D19: Capacity|Electricity|Fossil|w/ CCS | E19: GW
D20: Capacity|Electricity|Fossil|w/o CCS | E20: GW
D21: Capacity|Electricity|Gas | E21: GW
D22: Capacity|Electricity|Gas|w/ CCS | E22: GW
D23: Capacity|Electricity|Gas|w/o CCS | E23: GW
D24: Capacity|Electricity|Geothermal | E24: =VLOOKUP(D24,variable!$A$2:$D$12140,4,FALSE) -> GW
D25: Capacity|Electricity|Hydro | E25: =VLOOKUP(D25,variable!$A$2:$D$12140,4,FALSE) -> GW
D26: Capacity|Electricity|Hydrogen | E26: GW
D27: Capacity|Electricity|Non-Biomass Renewables | E27: GW
D28: Capacity|Electricity|Nuclear | E28: =VLOOKUP(D28,variable!$A$2:$D$12140,4,FALSE) -> GW
D29: Capacity|Electricity|Ocean | E29: GW
D30: Capacity|Electricity|Oil | E30: =VLOOKUP(D30,variable!$A$2:$D$12140,4,FALSE) -> GW
D31: Capacity|Electricity|Oil|w/ CCS | E31: GW
D32: Capacity|Electricity|Oil|w/o CCS | E32: =VLOOKUP(D32,variable!$A$2:$D$12140,4,FALSE) -> GW
D33: Capacity|Electricity|Other | E33: GW
D34: Capacity|Electricity|Solar | E34: =VLOOKUP(D34,variable!$A$2:$D$12140,4,FALSE) -> GW
D35: Capacity|Electricity|Solar|CSP | E35: GW
D36: Capacity|Electricity|Solar|PV | E36: GW
D37: Capacity|Electricity|Wind | E37: =VLOOKUP(D37,variable!$A$2:$D$12140,4,FALSE) -> GW
D38: Capacity|Electricity|Wind|Offshore | E38: GW
D39: Capacity|Electricity|Wind|Onshore | E39: GW
D40: Capital Cost|Electricity|Biomass | E40: =VLOOKUP(D40,variable!$A$2:$D$12140,4,FALSE) -> USD_2010/kW
...

Sheet All & Priority
A1: Model | B1: Scenario | C1: Region | D1: Variable | E1: Unit | F1: 2005 | G1: 2010 | H1: 2015 | I1: 2020 | J1: 2025 | K1: 2030 | L1: 2035 | M1: 2040 | N1: 2045 | O1: 2050 | P1: 2060 | Q1: 2070 | R1: 2080 | S1: 2090 | T1: 2100
D2: Agricultural Demand | E2: million t DM/yr
D3: Agricultural Demand|Crops | E3: million t DM/yr
D4: Agricultural Demand|Crops|Bioenergy | E4: million t DM/yr
D5: Agricultural Demand|Crops|Bioenergy|1st Generation | E5: million t DM/yr
D6: Agricultural Demand|Crops|Bioenergy|2nd generation | E6: million t DM/yr
D7: Agricultural Demand|Crops|Feed | E7: million t DM/yr
D8: Agricultural Demand|Crops|Feed|Cereals | E8: million t DM/yr
D9: Agricultural Demand|Crops|Feed|Oil Crops | E9: million t DM/yr
D10: Agricultural Demand|Crops|Feed|Other Crops | E10: million t DM/yr
D11: Agricultural Demand|Crops|Feed|Sugar Crops | E11: million t DM/yr
D12: Agricultural Demand|Crops|Food | E12: million t DM/yr
D13: Agricultural Demand|Crops|Food|Cereals | E13: million t DM/yr
... D7629: Emissions|VOC|Energy|Demand|Transportation|Domestic|Aviation | E7629: Mt VOC/yr

Sheet NOTES
A1: Worksheet | B1: Description | C1: Other
A2: data | B2: Sheet used by Reporting too to report outputs for ScenarioMIP scenario explorer
A3: Priority-Emissions | B3: Priority variables for Emissions reporting. Based on email by Jarmo Kikstra (11/12/2024) | C3: https://docs.google.com/spreadsheets/d/1HKfl21NX8wohPEHpHlmf5XithknPw8zjLpVe4MiOU9U/edit?gid=1877841403#gid=1877841403
A4: Priority-Energy | B4: Priority variables for Energy reporting. Based on email by Gunnar Luderer (16/12/2024)
A5: All Tier 1 & Priority | B5: Priority Variables (Emissions & Energy) as well as Tier 1 variables from variable worksheet
A6: All & Priority | B6: Priority Variables (Emissions & Energy) as well as all Variables (that also have units) from variable worksheet
